<?xml version="1.0" ?>
<!-- =================================================================================== -->
<!-- |    This document was autogenerated by xacro from robot.xacro                    | -->
<!-- |    EDITING THIS FILE BY HAND IS NOT RECOMMENDED                                 | -->
<!-- =================================================================================== -->
<robot name="robot" xmlns:xacro="http://www.ros.org/wiki/xacro">
  <!-- base of robot-->
  <link name="base_link">
    <visual>
      <geometry>
        <box size="0.4 0.3 0.125"/>
      </geometry>
      <material name="blue">
        <color rgba="0 0 .8 1"/>
      </material>
    </visual>
    <collision>
      <geometry>
        <box size="0.4 0.3 0.125"/>
      </geometry>
    </collision>
    <inertial>
      <mass value="7.0"/>
      <inertia ixx="0.00166666666667" ixy="0.0" ixz="0.0" iyy="0.102447916667" iyz="0.0" izz="0.145833333333"/>
    </inertial>
  </link>
  <!--wheels-->
  <link name="right_front_wheel">
    <visual>
      <geometry>
        <cylinder length="0.1" radius="0.1"/>
      </geometry>
      <material name="black">
        <color rgba="0 0 0 1"/>
      </material>
    </visual>
    <collision>
      <geometry>
        <cylinder length="0.1" radius="0.1"/>
      </geometry>
    </collision>
    <inertial>
      <mass value="0.5"/>
      <inertia ixx="0.00166666666667" ixy="0.0" ixz="0.0" iyy="0.00166666666667" iyz="0.0" izz="0.0025"/>
    </inertial>
  </link>
  <gazebo reference="{prefix}_wheel">
    <mu1 value="10"/>
    <mu2 value="0.5"/>
    <fdir value="1 0 0"/>
    <material>Gazebo/Black</material>
  </gazebo>
  <joint name="right_front_wheel_joint" type="continuous">
    <axis xyz="0 0 1"/>
    <parent link="base_link"/>
    <child link="right_front_wheel"/>
    <origin rpy="0 1.57079632679 1.57079632679" xyz="0.2 0.2 -0.03125"/>
    <limit effort="100" velocity="100"/>
    <joint_properties damping="0.0" friction="0.0"/>
  </joint>
  <link name="right_rear_wheel">
    <visual>
      <geometry>
        <cylinder length="0.1" radius="0.1"/>
      </geometry>
      <material name="black">
        <color rgba="0 0 0 1"/>
      </material>
    </visual>
    <collision>
      <geometry>
        <cylinder length="0.1" radius="0.1"/>
      </geometry>
    </collision>
    <inertial>
      <mass value="0.5"/>
      <inertia ixx="0.00166666666667" ixy="0.0" ixz="0.0" iyy="0.00166666666667" iyz="0.0" izz="0.0025"/>
    </inertial>
  </link>
  <gazebo reference="{prefix}_wheel">
    <mu1 value="10"/>
    <mu2 value="0.5"/>
    <fdir value="1 0 0"/>
    <material>Gazebo/Black</material>
  </gazebo>
  <joint name="right_rear_wheel_joint" type="continuous">
    <axis xyz="0 0 1"/>
    <parent link="base_link"/>
    <child link="right_rear_wheel"/>
    <origin rpy="0 1.57079632679 1.57079632679" xyz="-0.2 0.2 -0.03125"/>
    <limit effort="100" velocity="100"/>
    <joint_properties damping="0.0" friction="0.0"/>
  </joint>
  <link name="left_front_wheel">
    <visual>
      <geometry>
        <cylinder length="0.1" radius="0.1"/>
      </geometry>
      <material name="black">
        <color rgba="0 0 0 1"/>
      </material>
    </visual>
    <collision>
      <geometry>
        <cylinder length="0.1" radius="0.1"/>
      </geometry>
    </collision>
    <inertial>
      <mass value="0.5"/>
      <inertia ixx="0.00166666666667" ixy="0.0" ixz="0.0" iyy="0.00166666666667" iyz="0.0" izz="0.0025"/>
    </inertial>
  </link>
  <gazebo reference="{prefix}_wheel">
    <mu1 value="10"/>
    <mu2 value="0.5"/>
    <fdir value="1 0 0"/>
    <material>Gazebo/Black</material>
  </gazebo>
  <joint name="left_front_wheel_joint" type="continuous">
    <axis xyz="0 0 1"/>
    <parent link="base_link"/>
    <child link="left_front_wheel"/>
    <origin rpy="0 1.57079632679 1.57079632679" xyz="0.2 -0.2 -0.03125"/>
    <limit effort="100" velocity="100"/>
    <joint_properties damping="0.0" friction="0.0"/>
  </joint>
  <link name="left_rear_wheel">
    <visual>
      <geometry>
        <cylinder length="0.1" radius="0.1"/>
      </geometry>
      <material name="black">
        <color rgba="0 0 0 1"/>
      </material>
    </visual>
    <collision>
      <geometry>
        <cylinder length="0.1" radius="0.1"/>
      </geometry>
    </collision>
    <inertial>
      <mass value="0.5"/>
      <inertia ixx="0.00166666666667" ixy="0.0" ixz="0.0" iyy="0.00166666666667" iyz="0.0" izz="0.0025"/>
    </inertial>
  </link>
  <gazebo reference="{prefix}_wheel">
    <mu1 value="10"/>
    <mu2 value="0.5"/>
    <fdir value="1 0 0"/>
    <material>Gazebo/Black</material>
  </gazebo>
  <joint name="left_rear_wheel_joint" type="continuous">
    <axis xyz="0 0 1"/>
    <parent link="base_link"/>
    <child link="left_rear_wheel"/>
    <origin rpy="0 1.57079632679 1.57079632679" xyz="-0.2 -0.2 -0.03125"/>
    <limit effort="100" velocity="100"/>
    <joint_properties damping="0.0" friction="0.0"/>
  </joint>
  <joint name="hokuyo_joint" type="fixed">
    <origin rpy="0 0 0" xyz="0.1 0 0.1125"/>
    <parent link="base_link"/>
    <child link="hokuyo_link"/>
  </joint>
  <!-- Hokuyo Laser -->
  <link name="hokuyo_link">
    <collision>
      <geometry>
        <box size="0.1 0.1 0.1"/>
      </geometry>
    </collision>
    <visual>
      <geometry>
        <mesh filename="package://robot_description/meshes/hokuyo.dae"/>
      </geometry>
    </visual>
    <inertial>
      <mass value="1e-5"/>
      <inertia ixx="1e-6" ixy="0" ixz="0" iyy="1e-6" iyz="0" izz="1e-6"/>
    </inertial>
  </link>
  <gazebo reference="base_link">
    <material>Gazebo/Blue</material>
  </gazebo>
  <gazebo reference="right_front_wheel">
    <material>Gazebo/Black</material>
  </gazebo>
  <gazebo reference="right_rear_wheel">
    <material>Gazebo/Black</material>
  </gazebo>
  <gazebo reference="left_front_wheel">
    <material>Gazebo/Black</material>
  </gazebo>
  <gazebo reference="left_rear_wheel">
    <material>Gazebo/Black</material>
  </gazebo>
  <gazebo reference="hokuyo_link">
    <sensor name="head_hokuyo_sensor" type="gpu_ray">
      <visualize>false</visualize>
      <update_rate>40</update_rate>
      <ray>
        <scan>
          <horizontal>
            <samples>720</samples>
            <resolution>1</resolution>
            <min_angle>-1.570796</min_angle>
            <max_angle>1.570796</max_angle>
          </horizontal>
        </scan>
        <range>
          <min>0.10</min>
          <max>30.0</max>
          <resolution>0.01</resolution>
        </range>
        <noise>
          <type>gaussian</type>
          <mean>0.0</mean>
          <stddev>0.01</stddev>
        </noise>
      </ray>
      <plugin filename="libgazebo_ros_gpu_laser.so" name="gazebo_ros_head_hokuyo_controller">
        <topicName>/robot/laser/scan</topicName>
        <frameName>hokuyo_link</frameName>
      </plugin>
    </sensor>
  </gazebo>
  <!--diff drive contr-->
  <gazebo>
    <plugin filename="libgazebo_ros_plugin.so" name="robot_controller">
      <cmd_vel_topic_name>cmd_vel</cmd_vel_topic_name>
      <odom_topic_name>odom</odom_topic_name>
      <joint_states_topic_name>joint_states</joint_states_topic_name>
      <left_front_wheel_joint>left_front_wheel_joint</left_front_wheel_joint>
      <left_rear_wheel_joint>left_rear_wheel_joint</left_rear_wheel_joint>
      <right_front_wheel_joint>right_front_wheel_joint</right_front_wheel_joint>
      <right_rear_wheel_joint>right_rear_wheel_joint</right_rear_wheel_joint>
      <wheel_separation>0.4</wheel_separation>
      <updateRate>40.0</updateRate>
    </plugin>
  </gazebo>
  <transmission name="caster_rigth_front_wheel">
    <type>transmission_interface/SimpleTransmission</type>
    <joint name="rigth_front_wheel_joint"/>
    <actuator name="rigth_front_wheel_joint_motor">
      <hardwareInterface>EffortJointInterface</hardwareInterface>
      <mechanicalReduction>50</mechanicalReduction>
    </actuator>
  </transmission>
  <transmission name="caster_rigth_back_wheel">
    <type>transmission_interface/SimpleTransmission</type>
    <joint name="rigth_back_wheel_joint"/>
    <actuator name="rigth_back_wheel_joint_motor">
      <hardwareInterface>EffortJointInterface</hardwareInterface>
      <mechanicalReduction>50</mechanicalReduction>
    </actuator>
  </transmission>
  <transmission name="caster_left_front_wheel">
    <type>transmission_interface/SimpleTransmission</type>
    <joint name="left_front_wheel_joint"/>
    <actuator name="left_front_wheel_joint_motor">
      <hardwareInterface>EffortJointInterface</hardwareInterface>
      <mechanicalReduction>50</mechanicalReduction>
    </actuator>
  </transmission>
  <transmission name="caster_left_back_wheel">
    <type>transmission_interface/SimpleTransmission</type>
    <joint name="left_back_wheel_joint"/>
    <actuator name="left_back_wheel_joint_motor">
      <hardwareInterface>EffortJointInterface</hardwareInterface>
      <mechanicalReduction>50</mechanicalReduction>
    </actuator>
  </transmission>
</robot>
